Workbook

Sheet Dashboard
B2: Salud Móvil · Plan financiero B2B | N2: ESCENARIO (elige uno) | S2: =Supuestos!B6 -> 0.15
N3: Base | S3: =Modelo!B56 -> 155171.39
B4: ="Venta de la app a clínicas y hospitales · cifras en córdobas (C$) · horizonte 5 años · TMAR "&TEXT(Supuestos!B6,"0%") -> Venta de la app a clínicas y hospitales · cifras en córdobas (C$) · horizonte 5 años · TMAR 15% | N4: ▼ Pesimista · Base · Optimista | S4: =Modelo!B57 -> 0.26661661
B6: VAN (C$) | F6: TIR | J6: RCB (BENEFICIO / COSTO) | N6: PRI · RECUPERACIÓN (AÑOS)
B7: =Modelo!B56 -> 155171.39 | F7: =Modelo!B57 -> 0.26661661 | J7: =Modelo!B60 -> 1.0934291 | N7: =Modelo!B58 -> 3.8607486
B8: ="Al "&TEXT(Supuestos!B6,"0%")&" · criterio: mayor que 0" -> Al 15% · criterio: mayor que 0 | F8: ="vs TMAR "&TEXT(Supuestos!B6,"0%")&" · "&IF(ISNUMBER(Modelo!B57),IF(Modelo!B57>Supuestos!B6,"la supera","por debajo"),"no definida") -> vs TMAR 15% · la supera | J8: ="Criterio: mayor que 1 · RBC neto "&IF(ISNUMBER(Modelo!B61),TEXT(Modelo!B61,"0.00"),"n/d") -> Criterio: mayor que 1 · RBC neto 1.47 | N8: ="Descontado: "&IF(ISNUMBER(Modelo!B59),TEXT(Modelo!B59,"0.00")&" años","no se recupera") -> Descontado: 4.39 años
B10: INGRESOS AÑO 5 (C$) | F10: EBITDA AÑO 5 (C$) | J10: FINANCIAMIENTO MÁXIMO (C$) | N10: MÍNIMO ESTABLE (INSTITUCIONES)
B11: =Modelo!G26 -> 1530000 | F11: =Modelo!G34 -> 708200 | J11: =Modelo!B64 -> 349720 | N11: =Equilibrio!E32 -> 10
B12: ="Suscripciones: "&TEXT(Modelo!G24/Modelo!G26,"0%")&" del total" -> Suscripciones: 92% del total | F12: ="Margen EBITDA: "&TEXT(Modelo!G35,"0%") -> Margen EBITDA: 46% | J12: ="Recomendado reunir: C$ "&TEXT(Modelo!B65,"#,##0") -> Recomendado reunir: C$ 400,000 | N12: ="Estructura de costos del año "&Equilibrio!B25&" · equilibrio contable: "&Equilibrio!D32 -> Estructura de costos del año 3 · equilibrio contable: 8
B14: =IF(AND(ISNUMBER(Modelo!B57),Modelo!B56>0,Modelo!B57>Supuestos!B6),"VIABLE · Escenario "&Supuestos!B14&": VAN positivo, TIR sobre la TMAR y la inversión se recupera en "&IF(ISNUMBER(Modelo!B58),TEXT(Modelo!B58,"0.0")&" años","más de 5 años")&".","NO VIABLE · Escenario "&Supuestos!B14&": el VAN o la TIR no alcanzan el rendimiento mínimo exigido.") -> VIABLE · Escenario Base: VAN positivo, TIR sobre la TMAR y la inversión se recupera en 3.9 años.
B16: EVOLUCIÓN DEL NEGOCIO
B65: CÓMO USAR ESTE MODELO
B66: 1 · Elige el escenario arriba a la derecha (celda amarilla): todo el libro se recalcula.
B67: 2 · Cambia precios, instituciones por año, costos e inversión en la hoja Supuestos (celdas azules con fondo crema).
B68: 3 · Revisa los resultados en Modelo e Indicadores; el mínimo de instituciones para ser estable está en Equilibrio.
B69: 4 · Escenarios compara los tres casos a la vez; Planes resume qué recibe cada institución según lo que contrate.

Sheet Supuestos
A1: Supuestos del modelo
A2: Celdas en azul con fondo crema = valores editables · negro = fórmulas · verde = vínculos a otras hojas. Todo el libro se recalcula solo.
A4: 1 · Parámetros generales
A5: Tipo de cambio (C$ por US$) | B5: 36.6243 | H5: BCN: tipo de cambio oficial fijo en 2026 (deslizamiento 0%).
A6: TMAR (tasa mínima atractiva de rendimiento) | B6: 0.15 | H6: Supuesto de la conversación: compensa inflación, costo de oportunidad y riesgo.
A7: Impuesto sobre la renta (IR) | B7: 0.3 | H7: Supuesto a validar con un contador.
A8: Pago mínimo definitivo (% de ingresos brutos) | B8: 0.01 | H8: Supuesto a validar con un contador.
A9: Costo directo de implementación (% de la cuota) | B9: 0.3 | H9: Capacitación, viáticos y horas de configuración.
A10: Colchón de seguridad para el mínimo estable | B10: 0.2 | H10: 20% = aguantar la salida de 1 de cada 5 instituciones.
A11: Vida útil para amortizar la inversión (años) | B11: 5 | H11: Línea recta sobre toda la inversión inicial.
A12: Colchón sobre la necesidad de financiamiento | B12: 0.1 | H12: Se redondea hacia arriba a múltiplos de C$50,000.
A13: Ventas y marketing (% de los costos fijos) | B13: 0.25 | H13: Para calcular el CAC.
A14: Escenario activo (se cambia desde el Dashboard) | B14: =Dashboard!N3 -> Base
A16: 2 · Planes y precios por institución
A17: Plan | B17: Precio mensual (C$) | C17: Cuota de implementación (C$) | D17: Costo variable (% de la suscripción) | E17: Bajas anuales | F17: Pacientes activos por institución | G17: Precio mensual (US$) | H17: Precio por paciente al mes (C$)
A18: Esencial | B18: 2500 | C18: 5000 | D18: 0.1 | E18: 0.12 | F18: 250 | G18: =B18/$B$5 -> 68.26069 | H18: =IFERROR(B18/F18,0) -> 10
A19: Profesional | B19: 5000 | C19: 10000 | D19: 0.15 | E19: 0.08 | F19: 700 | G19: =B19/$B$5 -> 136.52138 | H19: =IFERROR(B19/F19,0) -> 7.1428571
A20: Premium | B20: 9000 | C20: 20000 | D20: 0.22 | E20: 0.05 | F20: 1500 | G20: =B20/$B$5 -> 245.73849 | H20: =IFERROR(B20/F20,0) -> 6
A21: Los precios, límites y costos por plan son supuestos de este plan; validarlos con clientes reales antes del lanzamiento.
A23: 3 · Instituciones de pago al cierre de cada año (netas de bajas)
A24: Plan | B24: Año 1 | C24: Año 2 | D24: Año 3 | E24: Año 4 | F24: Año 5
A25: Esencial | B25: 1 | C25: 2 | D25: 4 | E25: 7 | F25: 11 | H25: Conversación: 2, 5, 10, 18 y 30 instituciones de pago (no las 300 de cobertura).
A26: Profesional | B26: 1 | C26: 2 | D26: 4 | E26: 7 | F26: 13
A27: Premium | B27: 0 | C27: 1 | D27: 2 | E27: 4 | F27: 6
A28: Total instituciones al cierre | B28: =SUM(B25:B27) -> 2 | C28: =SUM(C25:C27) -> 5 | D28: =SUM(D25:D27) -> 10 | E28: =SUM(E25:E27) -> 18 | F28: =SUM(F25:F27) -> 30
A30: 4 · Costos fijos anuales (C$)
A31: Concepto | B31: Año 1 | C31: Año 2 | D31: Año 3 | E31: Año 4 | F31: Año 5 | G31: % del total
A32: Costos fijos totales | B32: 150000 | C32: 210000 | D32: 300000 | E32: 400000 | F32: 550000 | H32: Valores de la conversación; incluyen equipo, soporte, ventas, infraestructura y administración.
A33: Reparto por categoría (informativo)
A34: Equipo técnico (desarrollo y mantenimiento) | B34: =B$32*$G34 -> 60000 | C34: =C$32*$G34 -> 84000 | D34: =D$32*$G34 -> 120000 | E34: =E$32*$G34 -> 160000 | F34: =F$32*$G34 -> 220000 | G34: 0.4
A35: Soporte y éxito del cliente | B35: =B$32*$G35 -> 22500 | C35: =C$32*$G35 -> 31500 | D35: =D$32*$G35 -> 45000 | E35: =E$32*$G35 -> 60000 | F35: =F$32*$G35 -> 82500 | G35: 0.15
A36: Ventas y marketing B2B | B36: =B$32*$G36 -> 37500 | C36: =C$32*$G36 -> 52500 | D36: =D$32*$G36 -> 75000 | E36: =E$32*$G36 -> 100000 | F36: =F$32*$G36 -> 137500 | G36: 0.25
A37: Infraestructura base y seguridad | B37: =B$32*$G37 -> 15000 | C37: =C$32*$G37 -> 21000 | D37: =D$32*$G37 -> 30000 | E37: =E$32*$G37 -> 40000 | F37: =F$32*$G37 -> 55000 | G37: 0.1
A38: Administración, legal y contabilidad | B38: =B$32*$G38 -> 15000 | C38: =C$32*$G38 -> 21000 | D38: =D$32*$G38 -> 30000 | E38: =E$32*$G38 -> 40000 | F38: =F$32*$G38 -> 55000 | G38: 0.1
A39: Control: el reparto debe sumar 100% | G39: =SUM(G34:G38) -> 1 | H39: =IF(ROUND(G39,4)=1,"OK","Revisar: no suma 100%") -> OK
A41: 5 · Inversión inicial (C$)
A42: Concepto | B42: Monto (C$) | C42: Tratamiento
A43: Desarrollo / MVP | B43: 85000 | C43: Activo intangible
A44: Infraestructura y configuración | B44: 20000 | C44: Activo intangible
A45: Seguridad y privacidad | B45: 15000 | C45: Activo intangible
...

Sheet Planes
A1: Matriz de planes para instituciones
A2: Los precios y la cuota se leen de Supuestos; el resto de las celdas (azul) son texto editable. † = función que debe construirse en la app.
A4: Característica | B4: Esencial | C4: Profesional | D4: Premium
A5: Precio mensual por institución (C$) | B5: =Supuestos!B18 -> 2500 | C5: =Supuestos!B19 -> 5000 | D5: =Supuestos!B20 -> 9000
A6: Precio mensual (US$) | B6: =Supuestos!G18 -> 68.26069 | C6: =Supuestos!G19 -> 136.52138 | D6: =Supuestos!G20 -> 245.73849
A7: Cuota única de implementación (C$) | B7: =Supuestos!C18 -> 5000 | C7: =Supuestos!C19 -> 10000 | D7: =Supuestos!C20 -> 20000
A8: Pacientes activos incluidos | B8: hasta 300 | C8: hasta 1,000 | D8: sin límite
A9: Historial y datos por paciente | B9: 6 meses | C9: 24 meses | D9: sin límite
A10: Indicadores, citas, recordatorios, historial médico y emergencia | B10: Sí | C10: Sí | D10: Sí
A11: Medicamentos | B11: Registro manual | C11: Registro manual + 30 escaneos por paciente al mes † | D11: Escáner ilimitado †
A12: Actividad física | B12: No incluida | C12: Registro básico | D12: Registro completo con metas e historial
A13: Familiares y cuidadores vinculados | B13: 1 por paciente | C13: hasta 3 | D13: sin límite
A14: IPCP (priorización de pacientes) | B14: No incluido | C14: Sí | D14: Sí, con alertas al personal
A15: Recursos de salud | B15: Mapa de salud | C15: Mapa + referencias | D15: Mapa + referencias + tiempos de espera y guía de hospital
A16: Reportes institucionales | B16: Resumen mensual | C16: Tablero de uso | D16: Tablero + exportación + API †
A17: Soporte | B17: Correo (48 h) | C17: Correo y chat (24 h) | D17: Prioritario (4 h) y gestor de cuenta
A18: Marca propia | B18: No | C18: Logo de la institución | D18: Marca completa †
A19: Margen de contribución esperado del plan | B19: =1-Supuestos!D18 -> 0.9 | C19: =1-Supuestos!D19 -> 0.85 | D19: =1-Supuestos!D20 -> 0.78
A21: † No aparece en el código actual de la app móvil; su desarrollo debe entrar en la hoja de ruta de producto.

Sheet Modelo
A1: Modelo financiero a 5 años · escenario activo del Dashboard | G1: Escenario: | H1: =Supuestos!B14 -> Base
A2: C$ (córdobas) | B2: Año 0 | C2: Año 1 | D2: Año 2 | E2: Año 3 | F2: Año 4 | G2: Año 5 | H2: Total 5 años
A3: Período (t) | B3: 0 | C3: 1 | D3: 2 | E3: 3 | F3: 4 | G3: 5
A4: Instituciones de pago al cierre del año
A5: Esencial | B5: 0 | C5: =Supuestos!B25*Supuestos!$B$57 -> 1 | D5: =Supuestos!C25*Supuestos!$B$57 -> 2 | E5: =Supuestos!D25*Supuestos!$B$57 -> 4 | F5: =Supuestos!E25*Supuestos!$B$57 -> 7 | G5: =Supuestos!F25*Supuestos!$B$57 -> 11
A6: Profesional | B6: 0 | C6: =Supuestos!B26*Supuestos!$B$57 -> 1 | D6: =Supuestos!C26*Supuestos!$B$57 -> 2 | E6: =Supuestos!D26*Supuestos!$B$57 -> 4 | F6: =Supuestos!E26*Supuestos!$B$57 -> 7 | G6: =Supuestos!F26*Supuestos!$B$57 -> 13
A7: Premium | B7: 0 | C7: =Supuestos!B27*Supuestos!$B$57 -> 0 | D7: =Supuestos!C27*Supuestos!$B$57 -> 1 | E7: =Supuestos!D27*Supuestos!$B$57 -> 2 | F7: =Supuestos!E27*Supuestos!$B$57 -> 4 | G7: =Supuestos!F27*Supuestos!$B$57 -> 6
A8: Total al cierre | C8: =SUM(C5:C7) -> 2 | D8: =SUM(D5:D7) -> 5 | E8: =SUM(E5:E7) -> 10 | F8: =SUM(F5:F7) -> 18 | G8: =SUM(G5:G7) -> 30
A9: Instituciones facturadas (promedio del año)
A10: Esencial | C10: =(B5+C5)/2 -> 0.5 | D10: =(C5+D5)/2 -> 1.5 | E10: =(D5+E5)/2 -> 3 | F10: =(E5+F5)/2 -> 5.5 | G10: =(F5+G5)/2 -> 9
A11: Profesional | C11: =(B6+C6)/2 -> 0.5 | D11: =(C6+D6)/2 -> 1.5 | E11: =(D6+E6)/2 -> 3 | F11: =(E6+F6)/2 -> 5.5 | G11: =(F6+G6)/2 -> 10
A12: Premium | C12: =(B7+C7)/2 -> 0 | D12: =(C7+D7)/2 -> 0.5 | E12: =(D7+E7)/2 -> 1.5 | F12: =(E7+F7)/2 -> 3 | G12: =(F7+G7)/2 -> 5
A13: Total facturado | C13: =SUM(C10:C12) -> 1 | D13: =SUM(D10:D12) -> 3.5 | E13: =SUM(E10:E12) -> 7.5 | F13: =SUM(F10:F12) -> 14 | G13: =SUM(G10:G12) -> 24 | H13: =SUM(C13:G13) -> 50
A14: Altas
A15: Altas netas Esencial | C15: =MAX(0,C5-B5) -> 1 | D15: =MAX(0,D5-C5) -> 1 | E15: =MAX(0,E5-D5) -> 2 | F15: =MAX(0,F5-E5) -> 3 | G15: =MAX(0,G5-F5) -> 4
A16: Altas netas Profesional | C16: =MAX(0,C6-B6) -> 1 | D16: =MAX(0,D6-C6) -> 1 | E16: =MAX(0,E6-D6) -> 2 | F16: =MAX(0,F6-E6) -> 3 | G16: =MAX(0,G6-F6) -> 6
A17: Altas netas Premium | C17: =MAX(0,C7-B7) -> 0 | D17: =MAX(0,D7-C7) -> 1 | E17: =MAX(0,E7-D7) -> 1 | F17: =MAX(0,F7-E7) -> 2 | G17: =MAX(0,G7-F7) -> 2
A18: Altas netas totales | C18: =SUM(C15:C17) -> 2 | D18: =SUM(D15:D17) -> 3 | E18: =SUM(E15:E17) -> 5 | F18: =SUM(F15:F17) -> 8 | G18: =SUM(G15:G17) -> 12 | H18: =SUM(C18:G18) -> 30
A19: Altas brutas estimadas (netas + reposición de bajas) | C19: =C18+B5*Supuestos!$E$18+B6*Supuestos!$E$19+B7*Supuestos!$E$20 -> 2 | D19: =D18+C5*Supuestos!$E$18+C6*Supuestos!$E$19+C7*Supuestos!$E$20 -> 3.2 | E19: =E18+D5*Supuestos!$E$18+D6*Supuestos!$E$19+D7*Supuestos!$E$20 -> 5.45 | F19: =F18+E5*Supuestos!$E$18+E6*Supuestos!$E$19+E7*Supuestos!$E$20 -> 8.9 | G19: =G18+F5*Supuestos!$E$18+F6*Supuestos!$E$19+F7*Supuestos!$E$20 -> 13.6 | H19: =SUM(C19:G19) -> 33.15
A20: Ingresos (C$)
A21: Suscripción Esencial | C21: =C10*Supuestos!$B$18*Supuestos!$C$57*12 -> 15000 | D21: =D10*Supuestos!$B$18*Supuestos!$C$57*12 -> 45000 | E21: =E10*Supuestos!$B$18*Supuestos!$C$57*12 -> 90000 | F21: =F10*Supuestos!$B$18*Supuestos!$C$57*12 -> 165000 | G21: =G10*Supuestos!$B$18*Supuestos!$C$57*12 -> 270000 | H21: =SUM(C21:G21) -> 585000
A22: Suscripción Profesional | C22: =C11*Supuestos!$B$19*Supuestos!$C$57*12 -> 30000 | D22: =D11*Supuestos!$B$19*Supuestos!$C$57*12 -> 90000 | E22: =E11*Supuestos!$B$19*Supuestos!$C$57*12 -> 180000 | F22: =F11*Supuestos!$B$19*Supuestos!$C$57*12 -> 330000 | G22: =G11*Supuestos!$B$19*Supuestos!$C$57*12 -> 600000 | H22: =SUM(C22:G22) -> 1230000
A23: Suscripción Premium | C23: =C12*Supuestos!$B$20*Supuestos!$C$57*12 -> 0 | D23: =D12*Supuestos!$B$20*Supuestos!$C$57*12 -> 54000 | E23: =E12*Supuestos!$B$20*Supuestos!$C$57*12 -> 162000 | F23: =F12*Supuestos!$B$20*Supuestos!$C$57*12 -> 324000 | G23: =G12*Supuestos!$B$20*Supuestos!$C$57*12 -> 540000 | H23: =SUM(C23:G23) -> 1080000
A24: Ingresos por suscripción | C24: =SUM(C21:C23) -> 45000 | D24: =SUM(D21:D23) -> 189000 | E24: =SUM(E21:E23) -> 432000 | F24: =SUM(F21:F23) -> 819000 | G24: =SUM(G21:G23) -> 1410000 | H24: =SUM(C24:G24) -> 2895000
A25: Cuotas de implementación | C25: =(C15*Supuestos!$C$18+C16*Supuestos!$C$19+C17*Supuestos!$C$20)*Supuestos!$C$57 -> 15000 | D25: =(D15*Supuestos!$C$18+D16*Supuestos!$C$19+D17*Supuestos!$C$20)*Supuestos!$C$57 -> 35000 | E25: =(E15*Supuestos!$C$18+E16*Supuestos!$C$19+E17*Supuestos!$C$20)*Supuestos!$C$57 -> 50000 | F25: =(F15*Supuestos!$C$18+F16*Supuestos!$C$19+F17*Supuestos!$C$20)*Supuestos!$C$57 -> 85000 | G25: =(G15*Supuestos!$C$18+G16*Supuestos!$C$19+G17*Supuestos!$C$20)*Supuestos!$C$57 -> 120000 | H25: =SUM(C25:G25) -> 305000
A26: INGRESOS TOTALES | C26: =C24+C25 -> 60000 | D26: =D24+D25 -> 224000 | E26: =E24+E25 -> 482000 | F26: =F24+F25 -> 904000 | G26: =G24+G25 -> 1530000 | H26: =SUM(C26:G26) -> 3200000
A27: Costos (C$)
A28: Costos variables de la suscripción | C28: =(C21*Supuestos!$D$18+C22*Supuestos!$D$19+C23*Supuestos!$D$20)*Supuestos!$D$57 -> 6000 | D28: =(D21*Supuestos!$D$18+D22*Supuestos!$D$19+D23*Supuestos!$D$20)*Supuestos!$D$57 -> 29880 | E28: =(E21*Supuestos!$D$18+E22*Supuestos!$D$19+E23*Supuestos!$D$20)*Supuestos!$D$57 -> 71640 | F28: =(F21*Supuestos!$D$18+F22*Supuestos!$D$19+F23*Supuestos!$D$20)*Supuestos!$D$57 -> 137280 | G28: =(G21*Supuestos!$D$18+G22*Supuestos!$D$19+G23*Supuestos!$D$20)*Supuestos!$D$57 -> 235800 | H28: =SUM(C28:G28) -> 480600
A29: Costos directos de implementación | C29: =C25*Supuestos!$B$9 -> 4500 | D29: =D25*Supuestos!$B$9 -> 10500 | E29: =E25*Supuestos!$B$9 -> 15000 | F29: =F25*Supuestos!$B$9 -> 25500 | G29: =G25*Supuestos!$B$9 -> 36000 | H29: =SUM(C29:G29) -> 91500
A30: Costos variables totales | C30: =C28+C29 -> 10500 | D30: =D28+D29 -> 40380 | E30: =E28+E29 -> 86640 | F30: =F28+F29 -> 162780 | G30: =G28+G29 -> 271800 | H30: =SUM(C30:G30) -> 572100
A31: Costos fijos | C31: =Supuestos!B$32*Supuestos!$E$57 -> 150000 | D31: =Supuestos!C$32*Supuestos!$E$57 -> 210000 | E31: =Supuestos!D$32*Supuestos!$E$57 -> 300000 | F31: =Supuestos!E$32*Supuestos!$E$57 -> 400000 | G31: =Supuestos!F$32*Supuestos!$E$57 -> 550000 | H31: =SUM(C31:G31) -> 1610000
A32: COSTOS TOTALES | C32: =C30+C31 -> 160500 | D32: =D30+D31 -> 250380 | E32: =E30+E31 -> 386640 | F32: =F30+F31 -> 562780 | G32: =G30+G31 -> 821800 | H32: =SUM(C32:G32) -> 2182100
A33: Estado de resultados (C$)
A34: EBITDA | C34: =C26-C32 -> -100500 | D34: =D26-D32 -> -26380 | E34: =E26-E32 -> 95360 | F34: =F26-F32 -> 341220 | G34: =G26-G32 -> 708200 | H34: =SUM(C34:G34) -> 1017900
A35: Margen EBITDA | C35: =IF(C26=0,0,C34/C26) -> -1.675 | D35: =IF(D26=0,0,D34/D26) -> -0.11776786 | E35: =IF(E26=0,0,E34/E26) -> 0.19784232 | F35: =IF(F26=0,0,F34/F26) -> 0.37745575 | G35: =IF(G26=0,0,G34/G26) -> 0.46287582
A36: (–) Amortización de la inversión | C36: =IF(C3<=Supuestos!$B$11,Supuestos!$B$50/Supuestos!$B$11,0) -> 44000 | D36: =IF(D3<=Supuestos!$B$11,Supuestos!$B$50/Supuestos!$B$11,0) -> 44000 | E36: =IF(E3<=Supuestos!$B$11,Supuestos!$B$50/Supuestos!$B$11,0) -> 44000 | F36: =IF(F3<=Supuestos!$B$11,Supuestos!$B$50/Supuestos!$B$11,0) -> 44000 | G36: =IF(G3<=Supuestos!$B$11,Supuestos!$B$50/Supuestos!$B$11,0) -> 44000 | H36: =SUM(C36:G36) -> 220000
A37: Utilidad antes de impuestos | C37: =C34-C36 -> -144500 | D37: =D34-D36 -> -70380 | E37: =E34-E36 -> 51360 | F37: =F34-F36 -> 297220 | G37: =G34-G36 -> 664200 | H37: =SUM(C37:G37) -> 797900
A38: Pérdidas por compensar (inicio) | C38: =0 -> 0 | D38: =C40 -> 144500 | E38: =D40 -> 214880 | F38: =E40 -> 163520 | G38: =F40 -> 0
A39: Pérdidas compensadas en el año | C39: =MIN(C38,MAX(C37,0)) -> 0 | D39: =MIN(D38,MAX(D37,0)) -> 0 | E39: =MIN(E38,MAX(E37,0)) -> 51360 | F39: =MIN(F38,MAX(F37,0)) -> 163520 | G39: =MIN(G38,MAX(G37,0)) -> 0
A40: Pérdidas por compensar (cierre) | C40: =C38+MAX(-C37,0)-C39 -> 144500 | D40: =D38+MAX(-D37,0)-D39 -> 214880 | E40: =E38+MAX(-E37,0)-E39 -> 163520 | F40: =F38+MAX(-F37,0)-F39 -> 0 | G40: =G38+MAX(-G37,0)-G39 -> 0
...

Sheet Indicadores
A1: Indicadores de evaluación financiera
A2: Calculados sobre el flujo de caja libre después de impuestos del escenario activo.
A4: Indicador | B4: Resultado | C4: Criterio | D4: Lectura
A5: TMAR | B5: =Supuestos!B6 -> 0.15 | C5: Referencia | D5: ="Rendimiento mínimo exigido por los socios" -> Rendimiento mínimo exigido por los socios
A6: VAN (valor actual neto, C$) | B6: =Modelo!$B$56 -> 155171.39 | C6: Mayor que 0 | D6: =IF(B6>0,"Crea valor: queda "&TEXT(B6,"#,##0")&" por encima del rendimiento exigido","No alcanza el rendimiento exigido") -> Crea valor: queda 155,171 por encima del rendimiento exigido
A7: TIR (tasa interna de retorno) | B7: =Modelo!$B$57 -> 0.26661661 | C7: Mayor que la TMAR | D7: =IF(ISNUMBER(B7),IF(B7>B5,"Supera la TMAR por "&TEXT(B7-B5,"0.0%")&" puntos","Queda por debajo de la TMAR"),"No definida con estos flujos") -> Supera la TMAR por 11.7% puntos
A8: RCB (relación beneficio / costo) | B8: =Modelo!$B$60 -> 1.0934291 | C8: Mayor que 1 | D8: =IF(ISNUMBER(B8),IF(B8>1,"Por cada C$1 de egreso genera C$"&TEXT(B8,"0.00")&" de ingreso (valor presente)","Los egresos superan a los ingresos"),"n/d") -> Por cada C$1 de egreso genera C$1.09 de ingreso (valor presente)
A9: RBC sobre flujos netos (definición de la conversación) | B9: =Modelo!$B$61 -> 1.4708529 | C9: Mayor que 1 | D9: =IF(ISNUMBER(B9),IF(B9>1,"Flujos positivos cubren inversión y flujos negativos","No cubre la inversión"),"n/d") -> Flujos positivos cubren inversión y flujos negativos
A10: Índice de rentabilidad | B10: =Modelo!$B$62 -> 1.7053245 | C10: Mayor que 1 | D10: =IF(B10>1,"Cada C$1 invertido devuelve C$"&TEXT(B10,"0.00")&" en valor presente","Devuelve menos de lo invertido") -> Cada C$1 invertido devuelve C$1.71 en valor presente
A11: PRI (recuperación de la inversión, años) | B11: =Modelo!$B$58 -> 3.8607486 | C11: Menor que 5 años | D11: =IF(ISNUMBER(B11),"Se recupera en "&INT(B11)&" años y "&ROUND((B11-INT(B11))*12,0)&" meses","No se recupera en 5 años") -> Se recupera en 3 años y 10 meses
A12: PRI descontado (años) | B12: =Modelo!$B$59 -> 4.3867546 | C12: Menor que 5 años | D12: =IF(ISNUMBER(B12),"Con flujos descontados: "&INT(B12)&" años y "&ROUND((B12-INT(B12))*12,0)&" meses","No se recupera en 5 años") -> Con flujos descontados: 4 años y 5 meses
A13: ROI acumulado a 5 años | B13: =Modelo!$B$63 -> 2.5039545 | C13: Referencia | D13: ="(Flujo libre acumulado - inversión) / inversión, sin descontar" -> (Flujo libre acumulado - inversión) / inversión, sin descontar
A14: Necesidad máxima de financiamiento (C$) | B14: =Modelo!$B$64 -> 349720 | C14: Referencia | D14: ="Punto más bajo del flujo acumulado" -> Punto más bajo del flujo acumulado
A15: Financiamiento recomendado (C$) | B15: =Modelo!$B$65 -> 400000 | C15: Referencia | D15: ="Necesidad máxima más colchón, redondeado a C$50,000" -> Necesidad máxima más colchón, redondeado a C$50,000
A18: Cálculo del VAN y del flujo acumulado (C$)
A19: Concepto | B19: Año 0 | C19: Año 1 | D19: Año 2 | E19: Año 3 | F19: Año 4 | G19: Año 5
A20: Flujo de caja libre | B20: =Modelo!B47 -> -220000 | C20: =Modelo!C47 -> -101100 | D20: =Modelo!D47 -> -28620 | E20: =Modelo!E47 -> 90540 | F20: =Modelo!F47 -> 301110 | G20: =Modelo!G47 -> 508940
A21: Factor de descuento | B21: =Modelo!B49 -> 1 | C21: =Modelo!C49 -> 0.86956522 | D21: =Modelo!D49 -> 0.75614367 | E21: =Modelo!E49 -> 0.65751623 | F21: =Modelo!F49 -> 0.57175325 | G21: =Modelo!G49 -> 0.49717674
A22: Flujo descontado | B22: =Modelo!B50 -> -220000 | C22: =Modelo!C50 -> -87913.043 | D22: =Modelo!D50 -> -21640.832 | E22: =Modelo!E50 -> 59531.52 | F22: =Modelo!F50 -> 172160.62 | G22: =Modelo!G50 -> 253033.13
A23: Flujo acumulado | B23: =Modelo!B48 -> -220000 | C23: =Modelo!C48 -> -321100 | D23: =Modelo!D48 -> -349720 | E23: =Modelo!E48 -> -259180 | F23: =Modelo!F48 -> 41930 | G23: =Modelo!G48 -> 550870
A24: Flujo descontado acumulado | B24: =Modelo!B51 -> -220000 | C24: =Modelo!C51 -> -307913.04 | D24: =Modelo!D51 -> -329553.88 | E24: =Modelo!E51 -> -270022.36 | F24: =Modelo!F51 -> -97861.736 | G24: =Modelo!G51 -> 155171.39
A25: VAN = suma del flujo descontado | B25: =SUM(B22:G22) -> 155171.39
A28: Sensibilidad del VAN a la TMAR (C$)
A29: TMAR (editable) | B29: 0.1 | C29: 0.12 | D29: 0.15 | E29: 0.18 | F29: 0.2 | G29: 0.25 | H29: 0.3
A30: VAN a esa TMAR | B30: =SUMPRODUCT(Modelo!$B$47:$G$47/(1+B29)^Modelo!$B$3:$G$3) -> 254135.94 | C30: =SUMPRODUCT(Modelo!$B$47:$G$47/(1+C29)^Modelo!$B$3:$G$3) -> 211508.11 | D30: =SUMPRODUCT(Modelo!$B$47:$G$47/(1+D29)^Modelo!$B$3:$G$3) -> 155171.39 | E30: =SUMPRODUCT(Modelo!$B$47:$G$47/(1+E29)^Modelo!$B$3:$G$3) -> 106644.59 | F30: =SUMPRODUCT(Modelo!$B$47:$G$47/(1+F29)^Modelo!$B$3:$G$3) -> 78013.632 | G30: =SUMPRODUCT(Modelo!$B$47:$G$47/(1+G29)^Modelo!$B$3:$G$3) -> 17263.795 | H30: =SUMPRODUCT(Modelo!$B$47:$G$47/(1+H29)^Modelo!$B$3:$G$3) -> -30994.08
A31: La TIR es la TMAR a la cual el VAN se hace cero.

Sheet Equilibrio
A1: Punto de equilibrio y mínimo de instituciones para la estabilidad
A2: Cuántas instituciones de pago se necesitan según la estructura de costos de cada año (escenario activo).
A4: Concepto | B4: Unidad | C4: Año 1 | D4: Año 2 | E4: Año 3 | F4: Año 4 | G4: Año 5
A5: Costos fijos del año | B5: C$ | C5: =Modelo!C31 -> 150000 | D5: =Modelo!D31 -> 210000 | E5: =Modelo!E31 -> 300000 | F5: =Modelo!F31 -> 400000 | G5: =Modelo!G31 -> 550000
A6: Participación Esencial | B6: % | C6: =IFERROR(Modelo!C5/Modelo!C8,0) -> 0.5 | D6: =IFERROR(Modelo!D5/Modelo!D8,0) -> 0.4 | E6: =IFERROR(Modelo!E5/Modelo!E8,0) -> 0.4 | F6: =IFERROR(Modelo!F5/Modelo!F8,0) -> 0.38888889 | G6: =IFERROR(Modelo!G5/Modelo!G8,0) -> 0.36666667
A7: Participación Profesional | B7: % | C7: =IFERROR(Modelo!C6/Modelo!C8,0) -> 0.5 | D7: =IFERROR(Modelo!D6/Modelo!D8,0) -> 0.4 | E7: =IFERROR(Modelo!E6/Modelo!E8,0) -> 0.4 | F7: =IFERROR(Modelo!F6/Modelo!F8,0) -> 0.38888889 | G7: =IFERROR(Modelo!G6/Modelo!G8,0) -> 0.43333333
A8: Participación Premium | B8: % | C8: =IFERROR(Modelo!C7/Modelo!C8,0) -> 0 | D8: =IFERROR(Modelo!D7/Modelo!D8,0) -> 0.2 | E8: =IFERROR(Modelo!E7/Modelo!E8,0) -> 0.2 | F8: =IFERROR(Modelo!F7/Modelo!F8,0) -> 0.22222222 | G8: =IFERROR(Modelo!G7/Modelo!G8,0) -> 0.2
A9: Ingreso por suscripción por institución al año | B9: C$ | C9: =C6*Supuestos!$B$18*Supuestos!$C$57*12+C7*Supuestos!$B$19*Supuestos!$C$57*12+C8*Supuestos!$B$20*Supuestos!$C$57*12 -> 45000 | D9: =D6*Supuestos!$B$18*Supuestos!$C$57*12+D7*Supuestos!$B$19*Supuestos!$C$57*12+D8*Supuestos!$B$20*Supuestos!$C$57*12 -> 57600 | E9: =E6*Supuestos!$B$18*Supuestos!$C$57*12+E7*Supuestos!$B$19*Supuestos!$C$57*12+E8*Supuestos!$B$20*Supuestos!$C$57*12 -> 57600 | F9: =F6*Supuestos!$B$18*Supuestos!$C$57*12+F7*Supuestos!$B$19*Supuestos!$C$57*12+F8*Supuestos!$B$20*Supuestos!$C$57*12 -> 59000 | G9: =G6*Supuestos!$B$18*Supuestos!$C$57*12+G7*Supuestos!$B$19*Supuestos!$C$57*12+G8*Supuestos!$B$20*Supuestos!$C$57*12 -> 58600
A10: Margen de contribución por institución al año | B10: C$ | C10: =C6*Supuestos!$B$18*Supuestos!$C$57*12*(1-Supuestos!$D$18*Supuestos!$D$57)+C7*Supuestos!$B$19*Supuestos!$C$57*12*(1-Supuestos!$D$19*Supuestos!$D$57)+C8*Supuestos!$B$20*Supuestos!$C$57*12*(1-Supuestos!$D$20*Supuestos!$D$57) -> 39000 | D10: =D6*Supuestos!$B$18*Supuestos!$C$57*12*(1-Supuestos!$D$18*Supuestos!$D$57)+D7*Supuestos!$B$19*Supuestos!$C$57*12*(1-Supuestos!$D$19*Supuestos!$D$57)+D8*Supuestos!$B$20*Supuestos!$C$57*12*(1-Supuestos!$D$20*Supuestos!$D$57) -> 48048 | E10: =E6*Supuestos!$B$18*Supuestos!$C$57*12*(1-Supuestos!$D$18*Supuestos!$D$57)+E7*Supuestos!$B$19*Supuestos!$C$57*12*(1-Supuestos!$D$19*Supuestos!$D$57)+E8*Supuestos!$B$20*Supuestos!$C$57*12*(1-Supuestos!$D$20*Supuestos!$D$57) -> 48048 | F10: =F6*Supuestos!$B$18*Supuestos!$C$57*12*(1-Supuestos!$D$18*Supuestos!$D$57)+F7*Supuestos!$B$19*Supuestos!$C$57*12*(1-Supuestos!$D$19*Supuestos!$D$57)+F8*Supuestos!$B$20*Supuestos!$C$57*12*(1-Supuestos!$D$20*Supuestos!$D$57) -> 49053.333 | G10: =G6*Supuestos!$B$18*Supuestos!$C$57*12*(1-Supuestos!$D$18*Supuestos!$D$57)+G7*Supuestos!$B$19*Supuestos!$C$57*12*(1-Supuestos!$D$19*Supuestos!$D$57)+G8*Supuestos!$B$20*Supuestos!$C$57*12*(1-Supuestos!$D$20*Supuestos!$D$57) -> 48848
A11: Amortización anual | B11: C$ | C11: =Modelo!C36 -> 44000 | D11: =Modelo!D36 -> 44000 | E11: =Modelo!E36 -> 44000 | F11: =Modelo!F36 -> 44000 | G11: =Modelo!G36 -> 44000
A12: Equilibrio operativo (EBITDA = 0), exacto | B12: inst. | C12: =IFERROR(C5/C10,0) -> 3.8461538 | D12: =IFERROR(D5/D10,0) -> 4.3706294 | E12: =IFERROR(E5/E10,0) -> 6.2437562 | F12: =IFERROR(F5/F10,0) -> 8.1543898 | G12: =IFERROR(G5/G10,0) -> 11.259417
A13: Equilibrio contable (utilidad neta = 0), exacto | B13: inst. | C13: =IFERROR((C5+C11)/(C10-Supuestos!$B$8*C9),0) -> 5.0324254 | D13: =IFERROR((D5+D11)/(D10-Supuestos!$B$8*D9),0) -> 5.3505224 | E13: =IFERROR((E5+E11)/(E10-Supuestos!$B$8*E9),0) -> 7.2463768 | F13: =IFERROR((F5+F11)/(F10-Supuestos!$B$8*F9),0) -> 9.1615654 | G13: =IFERROR((G5+G11)/(G10-Supuestos!$B$8*G9),0) -> 12.30782
A14: Mínimo estable (equilibrio contable + colchón), exacto | B14: inst. | C14: =IFERROR(C13/(1-Supuestos!$B$10),0) -> 6.2905318 | D14: =IFERROR(D13/(1-Supuestos!$B$10),0) -> 6.688153 | E14: =IFERROR(E13/(1-Supuestos!$B$10),0) -> 9.057971 | F14: =IFERROR(F13/(1-Supuestos!$B$10),0) -> 11.451957 | G14: =IFERROR(G13/(1-Supuestos!$B$10),0) -> 15.384775
A15: Instituciones necesarias: equilibrio operativo | B15: inst. | C15: =ROUNDUP(C12,0) -> 4 | D15: =ROUNDUP(D12,0) -> 5 | E15: =ROUNDUP(E12,0) -> 7 | F15: =ROUNDUP(F12,0) -> 9 | G15: =ROUNDUP(G12,0) -> 12
A16: Instituciones necesarias: equilibrio contable | B16: inst. | C16: =ROUNDUP(C13,0) -> 6 | D16: =ROUNDUP(D13,0) -> 6 | E16: =ROUNDUP(E13,0) -> 8 | F16: =ROUNDUP(F13,0) -> 10 | G16: =ROUNDUP(G13,0) -> 13
A17: Instituciones necesarias: MÍNIMO ESTABLE | B17: inst. | C17: =ROUNDUP(C14,0) -> 7 | D17: =ROUNDUP(D14,0) -> 7 | E17: =ROUNDUP(E14,0) -> 10 | F17: =ROUNDUP(F14,0) -> 12 | G17: =ROUNDUP(G14,0) -> 16
A18: Instituciones proyectadas al cierre del año | B18: inst. | C18: =Modelo!C8 -> 2 | D18: =Modelo!D8 -> 5 | E18: =Modelo!E8 -> 10 | F18: =Modelo!F8 -> 18 | G18: =Modelo!G8 -> 30
A19: Colchón de la cartera proyectada sobre el mínimo estable | B19: % | C19: =IFERROR(C18/C17-1,0) -> -0.71428571 | D19: =IFERROR(D18/D17-1,0) -> -0.28571429 | E19: =IFERROR(E18/E17-1,0) -> 0 | F19: =IFERROR(F18/F17-1,0) -> 0.5 | G19: =IFERROR(G18/G17-1,0) -> 0.875
A20: Estado de la cartera proyectada | C20: =IF(C18>=C17,"Estable",IF(C18>=C16,"Sin colchón",IF(C18>=C15,"Equilibrio operativo","Bajo equilibrio"))) -> Bajo equilibrio | D20: =IF(D18>=D17,"Estable",IF(D18>=D16,"Sin colchón",IF(D18>=D15,"Equilibrio operativo","Bajo equilibrio"))) -> Equilibrio operativo | E20: =IF(E18>=E17,"Estable",IF(E18>=E16,"Sin colchón",IF(E18>=E15,"Equilibrio operativo","Bajo equilibrio"))) -> Estable | F20: =IF(F18>=F17,"Estable",IF(F18>=F16,"Sin colchón",IF(F18>=F15,"Equilibrio operativo","Bajo equilibrio"))) -> Estable | G20: =IF(G18>=G17,"Estable",IF(G18>=G16,"Sin colchón",IF(G18>=G15,"Equilibrio operativo","Bajo equilibrio"))) -> Estable
A21: Ingreso mensual por suscripciones del mínimo estable | B21: C$ | C21: =C17*C9/12 -> 26250 | D21: =D17*D9/12 -> 33600 | E21: =E17*E9/12 -> 48000 | F21: =F17*F9/12 -> 59000 | G21: =G17*G9/12 -> 78133.333
A24: Mínimo de instituciones según el plan contratado
A25: Año de la estructura de costos a evaluar (1 a 5) | B25: 3
A26: Costos fijos de ese año (C$) | B26: =INDEX(C5:G5,B25) -> 300000
A27: Amortización anual (C$) | B27: =INDEX(C11:G11,B25) -> 44000
A28: Si todas las instituciones fueran del plan | B28: Margen anual por institución (C$) | C28: Equilibrio operativo | D28: Equilibrio contable | E28: Mínimo estable
A29: Esencial | B29: =Supuestos!$B$18*Supuestos!$C$57*12*(1-Supuestos!$D$18*Supuestos!$D$57) -> 27000 | C29: =ROUNDUP($B$26/B29,0) -> 12 | D29: =ROUNDUP(($B$26+$B$27)/(B29-Supuestos!$B$8*Supuestos!$B$18*Supuestos!$C$57*12),0) -> 13 | E29: =ROUNDUP(($B$26+$B$27)/(B29-Supuestos!$B$8*Supuestos!$B$18*Supuestos!$C$57*12)/(1-Supuestos!$B$10),0) -> 17
A30: Profesional | B30: =Supuestos!$B$19*Supuestos!$C$57*12*(1-Supuestos!$D$19*Supuestos!$D$57) -> 51000 | C30: =ROUNDUP($B$26/B30,0) -> 6 | D30: =ROUNDUP(($B$26+$B$27)/(B30-Supuestos!$B$8*Supuestos!$B$19*Supuestos!$C$57*12),0) -> 7 | E30: =ROUNDUP(($B$26+$B$27)/(B30-Supuestos!$B$8*Supuestos!$B$19*Supuestos!$C$57*12)/(1-Supuestos!$B$10),0) -> 9
A31: Premium | B31: =Supuestos!$B$20*Supuestos!$C$57*12*(1-Supuestos!$D$20*Supuestos!$D$57) -> 84240 | C31: =ROUNDUP($B$26/B31,0) -> 4 | D31: =ROUNDUP(($B$26+$B$27)/(B31-Supuestos!$B$8*Supuestos!$B$20*Supuestos!$C$57*12),0) -> 5 | E31: =ROUNDUP(($B$26+$B$27)/(B31-Supuestos!$B$8*Supuestos!$B$20*Supuestos!$C$57*12)/(1-Supuestos!$B$10),0) -> 6
A32: Mezcla de planes de ese año | B32: =INDEX(C10:G10,B25) -> 48048 | C32: =ROUNDUP($B$26/B32,0) -> 7 | D32: =ROUNDUP(($B$26+$B$27)/(B32-Supuestos!$B$8*INDEX(C9:G9,B25)),0) -> 8 | E32: =ROUNDUP(($B$26+$B$27)/(B32-Supuestos!$B$8*INDEX(C9:G9,B25))/(1-Supuestos!$B$10),0) -> 10
A33: =" Un Premium aporta lo mismo que "&TEXT(B31/B29,"0.0")&" Esenciales o "&TEXT(B31/B30,"0.0")&" Profesionales." -> Un Premium aporta lo mismo que 3.1 Esenciales o 1.7 Profesionales.
A36: Costo de adquisición (CAC) y valor por cliente
A37: Concepto | B37: Unidad | C37: Año 1 | D37: Año 2 | E37: Año 3 | F37: Año 4 | G37: Año 5
A38: Ventas y marketing recurrente | B38: C$ | C38: =Supuestos!$B$13*C5 -> 37500 | D38: =Supuestos!$B$13*D5 -> 52500 | E38: =Supuestos!$B$13*E5 -> 75000 | F38: =Supuestos!$B$13*F5 -> 100000 | G38: =Supuestos!$B$13*G5 -> 137500
A39: Marketing de lanzamiento (inversión inicial) | B39: C$ | C39: =Supuestos!$B$46 -> 60000 | D39: =0 -> 0 | E39: =0 -> 0 | F39: =0 -> 0 | G39: =0 -> 0
A40: Altas brutas estimadas | B40: inst. | C40: =Modelo!C19 -> 2 | D40: =Modelo!D19 -> 3.2 | E40: =Modelo!E19 -> 5.45 | F40: =Modelo!F19 -> 8.9 | G40: =Modelo!G19 -> 13.6
A41: CAC del año por institución nueva | B41: C$ | C41: =IFERROR((C38+C39)/C40,0) -> 48750 | D41: =IFERROR((D38+D39)/D40,0) -> 16406.25 | E41: =IFERROR((E38+E39)/E40,0) -> 13761.468 | F41: =IFERROR((F38+F39)/F40,0) -> 11235.955 | G41: =IFERROR((G38+G39)/G40,0) -> 10110.294
A42: CAC promedio de los años 3 a 5 | B42: =IFERROR(SUM(E38:G38)/SUM(E40:G40),0) -> 11180.68
A44: Plan | B44: Margen anual por institución (C$) | C44: Años de cliente esperados en 5 años | D44: LTV a 5 años (C$) | E44: CAC (C$) | F44: LTV / CAC | G44: Recuperación del CAC (meses)
A45: Esencial | B45: =B29 -> 27000 | C45: =IFERROR((1-(1-Supuestos!$E$18)^5)/Supuestos!$E$18,5) -> 3.9355674 | D45: =B45*C45+Supuestos!$C$18*Supuestos!$C$57*(1-Supuestos!$B$9) -> 109760.32 | E45: =$B$42 -> 11180.68 | F45: =IFERROR(D45/E45,0) -> 9.8169629 | G45: =IFERROR(E45/(B45/12),0) -> 4.969191
A46: Profesional | B46: =B30 -> 51000 | C46: =IFERROR((1-(1-Supuestos!$E$19)^5)/Supuestos!$E$19,5) -> 4.261481 | D46: =B46*C46+Supuestos!$C$19*Supuestos!$C$57*(1-Supuestos!$B$9) -> 224335.53 | E46: =$B$42 -> 11180.68 | F46: =IFERROR(D46/E46,0) -> 20.06457 | G46: =IFERROR(E46/(B46/12),0) -> 2.6307482
...

Sheet Escenarios
A1: Comparación de escenarios
A2: Los tres escenarios se calculan a la vez en la hoja Calc_Esc; las palancas se editan en Supuestos (sección 6).
A4: Concepto | B4: Pesimista | C4: Base | D4: Optimista
A5: Instituciones (% del base) | B5: =Supuestos!B54 -> 0.6 | C5: =Supuestos!B55 -> 1 | D5: =Supuestos!B56 -> 1.3
A6: Precios (% de la lista) | B6: =Supuestos!C54 -> 0.9 | C6: =Supuestos!C55 -> 1 | D6: =Supuestos!C56 -> 1.05
A7: Costos variables (% del base) | B7: =Supuestos!D54 -> 1.2 | C7: =Supuestos!D55 -> 1 | D7: =Supuestos!D56 -> 0.95
A8: Instituciones al cierre del año 5 | B8: =Calc_Esc!G8 -> 18 | C8: =Calc_Esc!G75 -> 30 | D8: =Calc_Esc!G142 -> 39
A9: Ingresos del año 5 (C$) | B9: =Calc_Esc!G26 -> 826200 | C9: =Calc_Esc!G93 -> 1530000 | D9: =Calc_Esc!G160 -> 2088450
A10: EBITDA del año 5 (C$) | B10: =Calc_Esc!G34 -> 103961.6 | C10: =Calc_Esc!G101 -> 708200 | D10: =Calc_Esc!G168 -> 1183536.4
A11: VAN (C$) | B11: =Calc_Esc!B56 -> -442424.09 | C11: =Calc_Esc!B123 -> 155171.39 | D11: =Calc_Esc!B190 -> 558885.51
A12: TIR | B12: =Calc_Esc!B57 -> -0.41820138 | C12: =Calc_Esc!B124 -> 0.26661661 | D12: =Calc_Esc!B191 -> 0.5107954
A13: PRI (años) | B13: =Calc_Esc!B58 -> No se recupera | C13: =Calc_Esc!B125 -> 3.8607486 | D13: =Calc_Esc!B192 -> 3.0906869
A14: RCB | B14: =Calc_Esc!B60 -> 0.68910674 | C14: =Calc_Esc!B127 -> 1.0934291 | D14: =Calc_Esc!B194 -> 1.2910893
A15: Necesidad máxima de financiamiento (C$) | B15: =Calc_Esc!B64 -> 575818.4 | C15: =Calc_Esc!B131 -> 349720 | D15: =Calc_Esc!B198 -> 302842
A17: Los costos fijos no bajan en el escenario pesimista: el equipo necesario para atender el producto no se reduce si se venden menos planes.

Sheet Calc_Esc
A1: Escenario Pesimista · cálculo paralelo (no editar; se alimenta de Supuestos)
A2: C$ (córdobas) | B2: Año 0 | C2: Año 1 | D2: Año 2 | E2: Año 3 | F2: Año 4 | G2: Año 5 | H2: Total 5 años
A3: Período (t) | B3: 0 | C3: 1 | D3: 2 | E3: 3 | F3: 4 | G3: 5
A4: Instituciones de pago al cierre del año
A5: Esencial | B5: 0 | C5: =Supuestos!B25*Supuestos!$B$54 -> 0.6 | D5: =Supuestos!C25*Supuestos!$B$54 -> 1.2 | E5: =Supuestos!D25*Supuestos!$B$54 -> 2.4 | F5: =Supuestos!E25*Supuestos!$B$54 -> 4.2 | G5: =Supuestos!F25*Supuestos!$B$54 -> 6.6
A6: Profesional | B6: 0 | C6: =Supuestos!B26*Supuestos!$B$54 -> 0.6 | D6: =Supuestos!C26*Supuestos!$B$54 -> 1.2 | E6: =Supuestos!D26*Supuestos!$B$54 -> 2.4 | F6: =Supuestos!E26*Supuestos!$B$54 -> 4.2 | G6: =Supuestos!F26*Supuestos!$B$54 -> 7.8
A7: Premium | B7: 0 | C7: =Supuestos!B27*Supuestos!$B$54 -> 0 | D7: =Supuestos!C27*Supuestos!$B$54 -> 0.6 | E7: =Supuestos!D27*Supuestos!$B$54 -> 1.2 | F7: =Supuestos!E27*Supuestos!$B$54 -> 2.4 | G7: =Supuestos!F27*Supuestos!$B$54 -> 3.6
A8: Total al cierre | C8: =SUM(C5:C7) -> 1.2 | D8: =SUM(D5:D7) -> 3 | E8: =SUM(E5:E7) -> 6 | F8: =SUM(F5:F7) -> 10.8 | G8: =SUM(G5:G7) -> 18
A9: Instituciones facturadas (promedio del año)
A10: Esencial | C10: =(B5+C5)/2 -> 0.3 | D10: =(C5+D5)/2 -> 0.9 | E10: =(D5+E5)/2 -> 1.8 | F10: =(E5+F5)/2 -> 3.3 | G10: =(F5+G5)/2 -> 5.4
A11: Profesional | C11: =(B6+C6)/2 -> 0.3 | D11: =(C6+D6)/2 -> 0.9 | E11: =(D6+E6)/2 -> 1.8 | F11: =(E6+F6)/2 -> 3.3 | G11: =(F6+G6)/2 -> 6
A12: Premium | C12: =(B7+C7)/2 -> 0 | D12: =(C7+D7)/2 -> 0.3 | E12: =(D7+E7)/2 -> 0.9 | F12: =(E7+F7)/2 -> 1.8 | G12: =(F7+G7)/2 -> 3
A13: Total facturado | C13: =SUM(C10:C12) -> 0.6 | D13: =SUM(D10:D12) -> 2.1 | E13: =SUM(E10:E12) -> 4.5 | F13: =SUM(F10:F12) -> 8.4 | G13: =SUM(G10:G12) -> 14.4 | H13: =SUM(C13:G13) -> 30
A14: Altas
A15: Altas netas Esencial | C15: =MAX(0,C5-B5) -> 0.6 | D15: =MAX(0,D5-C5) -> 0.6 | E15: =MAX(0,E5-D5) -> 1.2 | F15: =MAX(0,F5-E5) -> 1.8 | G15: =MAX(0,G5-F5) -> 2.4
A16: Altas netas Profesional | C16: =MAX(0,C6-B6) -> 0.6 | D16: =MAX(0,D6-C6) -> 0.6 | E16: =MAX(0,E6-D6) -> 1.2 | F16: =MAX(0,F6-E6) -> 1.8 | G16: =MAX(0,G6-F6) -> 3.6
A17: Altas netas Premium | C17: =MAX(0,C7-B7) -> 0 | D17: =MAX(0,D7-C7) -> 0.6 | E17: =MAX(0,E7-D7) -> 0.6 | F17: =MAX(0,F7-E7) -> 1.2 | G17: =MAX(0,G7-F7) -> 1.2
A18: Altas netas totales | C18: =SUM(C15:C17) -> 1.2 | D18: =SUM(D15:D17) -> 1.8 | E18: =SUM(E15:E17) -> 3 | F18: =SUM(F15:F17) -> 4.8 | G18: =SUM(G15:G17) -> 7.2 | H18: =SUM(C18:G18) -> 18
A19: Altas brutas estimadas (netas + reposición de bajas) | C19: =C18+B5*Supuestos!$E$18+B6*Supuestos!$E$19+B7*Supuestos!$E$20 -> 1.2 | D19: =D18+C5*Supuestos!$E$18+C6*Supuestos!$E$19+C7*Supuestos!$E$20 -> 1.92 | E19: =E18+D5*Supuestos!$E$18+D6*Supuestos!$E$19+D7*Supuestos!$E$20 -> 3.27 | F19: =F18+E5*Supuestos!$E$18+E6*Supuestos!$E$19+E7*Supuestos!$E$20 -> 5.34 | G19: =G18+F5*Supuestos!$E$18+F6*Supuestos!$E$19+F7*Supuestos!$E$20 -> 8.16 | H19: =SUM(C19:G19) -> 19.89
A20: Ingresos (C$)
A21: Suscripción Esencial | C21: =C10*Supuestos!$B$18*Supuestos!$C$54*12 -> 8100 | D21: =D10*Supuestos!$B$18*Supuestos!$C$54*12 -> 24300 | E21: =E10*Supuestos!$B$18*Supuestos!$C$54*12 -> 48600 | F21: =F10*Supuestos!$B$18*Supuestos!$C$54*12 -> 89100 | G21: =G10*Supuestos!$B$18*Supuestos!$C$54*12 -> 145800 | H21: =SUM(C21:G21) -> 315900
A22: Suscripción Profesional | C22: =C11*Supuestos!$B$19*Supuestos!$C$54*12 -> 16200 | D22: =D11*Supuestos!$B$19*Supuestos!$C$54*12 -> 48600 | E22: =E11*Supuestos!$B$19*Supuestos!$C$54*12 -> 97200 | F22: =F11*Supuestos!$B$19*Supuestos!$C$54*12 -> 178200 | G22: =G11*Supuestos!$B$19*Supuestos!$C$54*12 -> 324000 | H22: =SUM(C22:G22) -> 664200
A23: Suscripción Premium | C23: =C12*Supuestos!$B$20*Supuestos!$C$54*12 -> 0 | D23: =D12*Supuestos!$B$20*Supuestos!$C$54*12 -> 29160 | E23: =E12*Supuestos!$B$20*Supuestos!$C$54*12 -> 87480 | F23: =F12*Supuestos!$B$20*Supuestos!$C$54*12 -> 174960 | G23: =G12*Supuestos!$B$20*Supuestos!$C$54*12 -> 291600 | H23: =SUM(C23:G23) -> 583200
A24: Ingresos por suscripción | C24: =SUM(C21:C23) -> 24300 | D24: =SUM(D21:D23) -> 102060 | E24: =SUM(E21:E23) -> 233280 | F24: =SUM(F21:F23) -> 442260 | G24: =SUM(G21:G23) -> 761400 | H24: =SUM(C24:G24) -> 1563300
A25: Cuotas de implementación | C25: =(C15*Supuestos!$C$18+C16*Supuestos!$C$19+C17*Supuestos!$C$20)*Supuestos!$C$54 -> 8100 | D25: =(D15*Supuestos!$C$18+D16*Supuestos!$C$19+D17*Supuestos!$C$20)*Supuestos!$C$54 -> 18900 | E25: =(E15*Supuestos!$C$18+E16*Supuestos!$C$19+E17*Supuestos!$C$20)*Supuestos!$C$54 -> 27000 | F25: =(F15*Supuestos!$C$18+F16*Supuestos!$C$19+F17*Supuestos!$C$20)*Supuestos!$C$54 -> 45900 | G25: =(G15*Supuestos!$C$18+G16*Supuestos!$C$19+G17*Supuestos!$C$20)*Supuestos!$C$54 -> 64800 | H25: =SUM(C25:G25) -> 164700
A26: INGRESOS TOTALES | C26: =C24+C25 -> 32400 | D26: =D24+D25 -> 120960 | E26: =E24+E25 -> 260280 | F26: =F24+F25 -> 488160 | G26: =G24+G25 -> 826200 | H26: =SUM(C26:G26) -> 1728000
A27: Costos (C$)
A28: Costos variables de la suscripción | C28: =(C21*Supuestos!$D$18+C22*Supuestos!$D$19+C23*Supuestos!$D$20)*Supuestos!$D$54 -> 3888 | D28: =(D21*Supuestos!$D$18+D22*Supuestos!$D$19+D23*Supuestos!$D$20)*Supuestos!$D$54 -> 19362.24 | E28: =(E21*Supuestos!$D$18+E22*Supuestos!$D$19+E23*Supuestos!$D$20)*Supuestos!$D$54 -> 46422.72 | F28: =(F21*Supuestos!$D$18+F22*Supuestos!$D$19+F23*Supuestos!$D$20)*Supuestos!$D$54 -> 88957.44 | G28: =(G21*Supuestos!$D$18+G22*Supuestos!$D$19+G23*Supuestos!$D$20)*Supuestos!$D$54 -> 152798.4 | H28: =SUM(C28:G28) -> 311428.8
A29: Costos directos de implementación | C29: =C25*Supuestos!$B$9 -> 2430 | D29: =D25*Supuestos!$B$9 -> 5670 | E29: =E25*Supuestos!$B$9 -> 8100 | F29: =F25*Supuestos!$B$9 -> 13770 | G29: =G25*Supuestos!$B$9 -> 19440 | H29: =SUM(C29:G29) -> 49410
A30: Costos variables totales | C30: =C28+C29 -> 6318 | D30: =D28+D29 -> 25032.24 | E30: =E28+E29 -> 54522.72 | F30: =F28+F29 -> 102727.44 | G30: =G28+G29 -> 172238.4 | H30: =SUM(C30:G30) -> 360838.8
A31: Costos fijos | C31: =Supuestos!B$32*Supuestos!$E$54 -> 150000 | D31: =Supuestos!C$32*Supuestos!$E$54 -> 210000 | E31: =Supuestos!D$32*Supuestos!$E$54 -> 300000 | F31: =Supuestos!E$32*Supuestos!$E$54 -> 400000 | G31: =Supuestos!F$32*Supuestos!$E$54 -> 550000 | H31: =SUM(C31:G31) -> 1610000
A32: COSTOS TOTALES | C32: =C30+C31 -> 156318 | D32: =D30+D31 -> 235032.24 | E32: =E30+E31 -> 354522.72 | F32: =F30+F31 -> 502727.44 | G32: =G30+G31 -> 722238.4 | H32: =SUM(C32:G32) -> 1970838.8
A33: Estado de resultados (C$)
A34: EBITDA | C34: =C26-C32 -> -123918 | D34: =D26-D32 -> -114072.24 | E34: =E26-E32 -> -94242.72 | F34: =F26-F32 -> -14567.44 | G34: =G26-G32 -> 103961.6 | H34: =SUM(C34:G34) -> -242838.8
A35: Margen EBITDA | C35: =IF(C26=0,0,C34/C26) -> -3.8246296 | D35: =IF(D26=0,0,D34/D26) -> -0.94305754 | E35: =IF(E26=0,0,E34/E26) -> -0.36208207 | F35: =IF(F26=0,0,F34/F26) -> -0.029841527 | G35: =IF(G26=0,0,G34/G26) -> 0.12583103
A36: (–) Amortización de la inversión | C36: =IF(C3<=Supuestos!$B$11,Supuestos!$B$50/Supuestos!$B$11,0) -> 44000 | D36: =IF(D3<=Supuestos!$B$11,Supuestos!$B$50/Supuestos!$B$11,0) -> 44000 | E36: =IF(E3<=Supuestos!$B$11,Supuestos!$B$50/Supuestos!$B$11,0) -> 44000 | F36: =IF(F3<=Supuestos!$B$11,Supuestos!$B$50/Supuestos!$B$11,0) -> 44000 | G36: =IF(G3<=Supuestos!$B$11,Supuestos!$B$50/Supuestos!$B$11,0) -> 44000 | H36: =SUM(C36:G36) -> 220000
A37: Utilidad antes de impuestos | C37: =C34-C36 -> -167918 | D37: =D34-D36 -> -158072.24 | E37: =E34-E36 -> -138242.72 | F37: =F34-F36 -> -58567.44 | G37: =G34-G36 -> 59961.6 | H37: =SUM(C37:G37) -> -462838.8
A38: Pérdidas por compensar (inicio) | C38: =0 -> 0 | D38: =C40 -> 167918 | E38: =D40 -> 325990.24 | F38: =E40 -> 464232.96 | G38: =F40 -> 522800.4
A39: Pérdidas compensadas en el año | C39: =MIN(C38,MAX(C37,0)) -> 0 | D39: =MIN(D38,MAX(D37,0)) -> 0 | E39: =MIN(E38,MAX(E37,0)) -> 0 | F39: =MIN(F38,MAX(F37,0)) -> 0 | G39: =MIN(G38,MAX(G37,0)) -> 59961.6
A40: Pérdidas por compensar (cierre) | C40: =C38+MAX(-C37,0)-C39 -> 167918 | D40: =D38+MAX(-D37,0)-D39 -> 325990.24 | E40: =E38+MAX(-E37,0)-E39 -> 464232.96 | F40: =F38+MAX(-F37,0)-F39 -> 522800.4 | G40: =G38+MAX(-G37,0)-G39 -> 462838.8
...
